2022-10-15 09:12:10,236 INFO    StreamThr :25764 [internal.py:wandb_internal():88] W&B internal server running at pid: 25764, started at: 2022-10-15 09:12:10.233539
2022-10-15 09:12:10,238 DEBUG   HandlerThread:25764 [handler.py:handle_request():138] handle_request: status
2022-10-15 09:12:10,240 DEBUG   SenderThread:25764 [sender.py:send_request():315] send_request: status
2022-10-15 09:12:10,241 INFO    WriterThread:25764 [datastore.py:open_for_write():75] open: /Users/christianjensen/Library/CloudStorage/OneDrive-UniversityofCopenhagen/2 - Projects/NLP Course/NLP-2022/wandb/run-20221015_091210-3giuv0ls/run-3giuv0ls.wandb
2022-10-15 09:12:10,242 DEBUG   SenderThread:25764 [sender.py:send():301] send: header
2022-10-15 09:12:10,261 DEBUG   SenderThread:25764 [sender.py:send():301] send: run
2022-10-15 09:12:43,714 ERROR   SenderThread:25764 [retry.py:__call__():154] Retry attempt failed:
Traceback (most recent call last):
  File "/opt/homebrew/lib/python3.9/site-packages/urllib3/connection.py", line 169, in _new_conn
    conn = connection.create_connection(
  File "/opt/homebrew/lib/python3.9/site-packages/urllib3/util/connection.py", line 96, in create_connection
    raise err
  File "/opt/homebrew/lib/python3.9/site-packages/urllib3/util/connection.py", line 86, in create_connection
    sock.connect(sa)
socket.timeout: timed out

During handling of the above exception, another exception occurred:

Traceback (most recent call last):
  File "/opt/homebrew/lib/python3.9/site-packages/urllib3/connectionpool.py", line 699, in urlopen
    httplib_response = self._make_request(
  File "/opt/homebrew/lib/python3.9/site-packages/urllib3/connectionpool.py", line 382, in _make_request
    self._validate_conn(conn)
  File "/opt/homebrew/lib/python3.9/site-packages/urllib3/connectionpool.py", line 1010, in _validate_conn
    conn.connect()
  File "/opt/homebrew/lib/python3.9/site-packages/urllib3/connection.py", line 353, in connect
    conn = self._new_conn()
  File "/opt/homebrew/lib/python3.9/site-packages/urllib3/connection.py", line 174, in _new_conn
    raise ConnectTimeoutError(
urllib3.exceptions.ConnectTimeoutError: (<urllib3.connection.HTTPSConnection object at 0x113998d00>, 'Connection to api.wandb.ai timed out. (connect timeout=10)')

During handling of the above exception, another exception occurred:

Traceback (most recent call last):
  File "/opt/homebrew/lib/python3.9/site-packages/requests/adapters.py", line 439, in send
    resp = conn.urlopen(
  File "/opt/homebrew/lib/python3.9/site-packages/urllib3/connectionpool.py", line 755, in urlopen
    retries = retries.increment(
  File "/opt/homebrew/lib/python3.9/site-packages/urllib3/util/retry.py", line 574, in increment
    raise MaxRetryError(_pool, url, error or ResponseError(cause))
urllib3.exceptions.MaxRetryError: HTTPSConnectionPool(host='api.wandb.ai', port=443): Max retries exceeded with url: /graphql (Caused by ConnectTimeoutError(<urllib3.connection.HTTPSConnection object at 0x113998d00>, 'Connection to api.wandb.ai timed out. (connect timeout=10)'))

During handling of the above exception, another exception occurred:

Traceback (most recent call last):
  File "/opt/homebrew/lib/python3.9/site-packages/wandb/sdk/lib/retry.py", line 113, in __call__
    result = self._call_fn(*args, **kwargs)
  File "/opt/homebrew/lib/python3.9/site-packages/wandb/sdk/internal/internal_api.py", line 199, in execute
    return self.client.execute(*args, **kwargs)  # type: ignore
  File "/opt/homebrew/lib/python3.9/site-packages/wandb/vendor/gql-0.2.0/wandb_gql/client.py", line 52, in execute
    result = self._get_result(document, *args, **kwargs)
  File "/opt/homebrew/lib/python3.9/site-packages/wandb/vendor/gql-0.2.0/wandb_gql/client.py", line 60, in _get_result
    return self.transport.execute(document, *args, **kwargs)
  File "/opt/homebrew/lib/python3.9/site-packages/wandb/vendor/gql-0.2.0/wandb_gql/transport/requests.py", line 38, in execute
    request = requests.post(self.url, **post_args)
  File "/opt/homebrew/lib/python3.9/site-packages/requests/api.py", line 117, in post
    return request('post', url, data=data, json=json, **kwargs)
  File "/opt/homebrew/lib/python3.9/site-packages/requests/api.py", line 61, in request
    return session.request(method=method, url=url, **kwargs)
  File "/opt/homebrew/lib/python3.9/site-packages/requests/sessions.py", line 542, in request
    resp = self.send(prep, **send_kwargs)
  File "/opt/homebrew/lib/python3.9/site-packages/requests/sessions.py", line 655, in send
    r = adapter.send(request, **kwargs)
  File "/opt/homebrew/lib/python3.9/site-packages/requests/adapters.py", line 504, in send
    raise ConnectTimeout(e, request=request)
requests.exceptions.ConnectTimeout: HTTPSConnectionPool(host='api.wandb.ai', port=443): Max retries exceeded with url: /graphql (Caused by ConnectTimeoutError(<urllib3.connection.HTTPSConnection object at 0x113998d00>, 'Connection to api.wandb.ai timed out. (connect timeout=10)'))
2022-10-15 09:14:13,490 DEBUG   HandlerThread:25764 [handler.py:handle_request():138] handle_request: poll_exit
2022-10-15 09:14:19,382 INFO    MainThread:25764 [internal.py:handle_exit():78] Internal process exited
2022-10-15 09:14:19,383 WARNING MsgRouterThr:25764 [router.py:message_loop():74] EOFError seen in message_loop
